Workbook

Sheet Datos
A1: Sampues - # 52-II-C-PZ-01 | E1: Finca el socorro (Ovejas) - # 44-II-D-PO-02 | H1: Ovejas - # 44-II-D-PO-05 | K1: Ovejas - # 44-II-D-PO-14 | N1: Los Palmitos - # 44-IV-B-PZ-01 Piñal | Q1: Morroa (Bremen) - # 44-IV-C-PZ-01 A | T1: Bremen - # 44-IV-C-PZ-01 B | W1: Las Tinas (Morroa) - # 44-IV-C-PZ-02 A | Z1: Las Tinas (Morroa) - # 44-IV-C-PZ-02 B | AC1: Arroyo salida a Betulia (Corozal) - # 44-IV-D-PZ-01 A | AF1: Arroyo salida a Betulia (Corozal) - # 44-IV-D-PZ-01 B | AI1: Sabanas de cali (El Tesoro) - # 44-IV-D-PZ-02 | AL1: Finca el tesoro - # 44-IV-D-PZ-04 | AO1: Basurero Viejo, Pileta (Corozal) - # 52-II-B-PZ-01 A | AR1: Basurero Viejo, Pileta (Corozal) - # 52-II-B-PZ-01 B | AU1: Insignares - # 44-IV-D-PO-02 | AX1: Corozal - # 44-IV-D-PO-14 | BA1: Corozal - # 44-IV-D-PZ-20 | BD1: Corozal - # 44-IV-D-PZ-22 | BG1: Cantagallo - # 52-II-A-PZ-01 Corozal | BJ1: Sampues - # 52-II-C-PZ-01
A2: Fecha Medida | B2: Nivel Estático (m) | C2: Nivel Piezometrico | E2: Fecha Medida | F2: Nivel Estático (m) | G2: Nivel Piezometrico | H2: Fecha Medida | I2: Nivel Estático (m) | J2: Nivel Piezometrico | K2: Fecha Medida | L2: Nivel Estático (m) | M2: Nivel Piezometrico | N2: Fecha Medida | O2: Nivel Estático (m) | P2: Nivel Piezometrico | Q2: Fecha Medida | R2: Nivel Estático (m) | S2: Nivel Piezometrico | T2: Fecha Medida | U2: Nivel Estático (m) | V2: Nivel Piezometrico | W2: Fecha Medida | X2: Nivel Estático (m) | Y2: Nivel Piezometrico | Z2: Fecha Medida | AA2: Nivel Estático (m) | AB2: Nivel Piezometrico | AC2: Fecha Medida | AD2: Nivel Estático (m) | AE2: Nivel Piezometrico | AF2: Fecha Medida | AG2: Nivel Estático (m) | AH2: Nivel Piezometrico | AI2: Fecha Medida | AJ2: Nivel Estático (m) | AK2: Nivel Piezometrico | AL2: Fecha Medida | AM2: Nivel Estático (m) | AN2: Nivel Piezometrico | AO2: Fecha Medida | AP2: Nivel Estático (m) | AQ2: Nivel Piezometrico | AR2: Fecha Medida | AS2: Nivel Estático (m) | AT2: Nivel Piezometrico | AU2: Fecha Medida | AV2: Nivel Estático (m) | AW2: Nivel Piezometrico | AX2: Fecha Medida | AY2: Nivel Estático (m) | AZ2: Nivel Piezometrico | BA2: Fecha Medida | BB2: Nivel Estático (m) | BC2: Nivel Piezometrico | BD2: Fecha Medida | BE2: Nivel Estático (m) | BF2: Nivel Piezometrico | BG2: Fecha Medida | BH2: Nivel Estático (m) | BI2: Nivel Piezometrico | BJ2: Fecha Medida | BK2: Nivel Estático (m) | BL2: Nivel Piezometrico
A3: 40224 | B3: 34.45 | C3: 140.55 | E3: 40254 | F3: 10.27436 | G3: 187.84 | H3: 41032 | I3: 13.72 | J3: 209.28 | K3: 40296 | L3: 8.11 | M3: 192.33 | N3: 40224 | O3: 72.08 | P3: 180.92 | Q3: 40190 | R3: 4.59 | S3: 165 | T3: 40190 | U3: 4.59 | V3: 165.55 | W3: 40184 | X3: 37.63 | Y3: 120.87 | Z3: 40227 | AA3: 2.89 | AB3: 146.32 | AC3: 40214 | AD3: 43.56 | AE3: 113.03 | AF3: 40227 | AG3: 6.94 | AH3: 137.36 | AI3: Fecha Medida | AJ3: Nivel Estático (m) | AK3: 118.21 | AL3: 40190 | AM3: 59.55 | AN3: 127.37 | AO3: 40214 | AP3: 36.1 | AQ3: 134.39 | AR3: 37617 | AS3: 23.73 | AT3: 140.92 | AU3: 37155 | AV3: 71.08 | AW3: 90.16 | AX3: 40214 | AY3: 61.48 | AZ3: 102.62 | BA3: 38364 | BB3: 10.8 | BC3: 130.58 | BD3: 40190 | BE3: 66.24 | BF3: 101.46 | BG3: 40214 | BH3: 34.17 | BI3: 136.83 | BJ3: 40224 | BK3: 34.45 | BL3: 140.55
A4: 40235 | B4: 34.98 | C4: 140.02 | E4: 40377 | F4: 10.22 | G4: 187.66 | H4: 41401 | I4: 17.69 | J4: 205.31 | K4: 40433 | L4: 8.34 | M4: 189.52 | N4: 40235 | O4: 72.5 | P4: 180.5 | Q4: 40238 | R4: 6.4 | S4: 164.97 | T4: 40238 | U4: 6.96 | V4: 165.45 | W4: 40313 | X4: 36.87 | Y4: 121.25 | Z4: 40372 | AA4: 2.93 | AB4: 145.74 | AC4: 40235 | AD4: 44.35 | AE4: 114.89 | AF4: 40372 | AG4: 7.3 | AH4: 137.09 | AI4: 40190 | AJ4: 89.7 | AK4: 118.21 | AL4: 40238 | AM4: 60.06 | AN4: 127.48 | AO4: 40235 | AP4: 36.3 | AQ4: 133.81 | AR4: 37635 | AS4: 24.36 | AT4: 140.29 | AU4: 37169 | AV4: 71.04 | AW4: 90.2 | AX4: 40235 | AY4: 62.56 | AZ4: 102.28 | BA4: 38378 | BB4: 10.94 | BC4: 130.44 | BD4: 40235 | BE4: 66.9 | BF4: 101.46 | BG4: 40224 | BH4: 33.81 | BI4: 137.19 | BJ4: 40235 | BK4: 34.98 | BL4: 140.02
A5: 40287 | B5: 33.85 | C5: 141.15 | E5: 40531 | F5: 10.23 | G5: 188.58 | H5: 41506 | I5: 16.28 | J5: 206.72 | K5: 40636 | L5: 8.5 | M5: 188.17 | N5: 40242 | O5: 72.5 | P5: 180.5 | Q5: 40287 | R5: 5.76 | S5: 165.02 | T5: 40287 | U5: 5.54 | V5: 165.39 | W5: 40494 | X5: 36.21 | Y5: 121.15 | Z5: 40540 | AA5: 2.96 | AB5: 146.22 | AC5: 40287 | AD5: 43.86 | AE5: 113.18 | AF5: 40540 | AG5: 7.49 | AH5: 136.82 | AI5: 40242 | AJ5: 91.01 | AK5: 118.41 | AL5: 40242 | AM5: 61.16 | AN5: 127.5 | AO5: 40287 | AP5: 36.55 | AQ5: 134.28 | AR5: 37642 | AS5: 23.03 | AT5: 141.62 | AU5: 37180 | AV5: 71.11 | AW5: 90.13 | AX5: 40287 | AY5: 62.5 | AZ5: 102.3 | BA5: 38442 | BB5: 11.16 | BC5: 130.22 | BD5: 40287 | BE5: 66.98 | BF5: 101.46 | BG5: 40235 | BH5: 34.2 | BI5: 136.8 | BJ5: 40287 | BK5: 33.85 | BL5: 141.15
A6: 40305 | B6: 34.87 | C6: 140.13 | E6: 40607 | F6: 10.232 | G6: 188.45 | H6: 41556 | I6: 16.85 | J6: 206.15 | K6: 40848 | L6: 8.79 | M6: 190.87 | N6: 40287 | O6: 71.98 | P6: 181.02 | Q6: 40331 | R6: 5.71 | S6: 164.9 | T6: 40331 | U6: 5.61 | V6: 165.59 | W6: 40506 | X6: 37.25 | Y6: 121.36 | Z6: 40640 | AA6: 3.13 | AB6: 145.79 | AC6: 40305 | AD6: 43.57 | AE6: 114.46 | AF6: 40575 | AG6: 7.6 | AH6: 137.08 | AI6: 40244 | AJ6: 91.02 | AK6: 118.32 | AL6: 40243 | AM6: 61.14 | AN6: 127.47 | AO6: 40305 | AP6: 36.36 | AQ6: 134.37 | AR6: 37720 | AS6: 24.01 | AT6: 140.64 | AU6: 37232 | AV6: 71.32 | AW6: 89.92 | AX6: 40305 | AY6: 62.34 | AZ6: 102.16 | BA6: 38446 | BB6: 11.03 | BC6: 130.35 | BD6: 40305 | BE6: 66.81 | BF6: 101.44 | BG6: 40242 | BH6: 34.8 | BI6: 136.2 | BJ6: 40305 | BK6: 34.87 | BL6: 140.13
A7: 40331 | B7: 34.07 | C7: 140.93 | E7: 40766 | F7: 10.2 | G7: 188.54 | H7: 41617 | I7: 15.25 | J7: 207.75 | K7: 40953 | L7: 8.63 | M7: 189.4 | N7: 40331 | O7: 71.78 | P7: 181.22 | Q7: 40393 | R7: 5.65 | S7: 164.94 | T7: 40393 | U7: 5.3 | V7: 165.4 | W7: 40660 | X7: 36.71 | Y7: 121.03 | Z7: 40810 | AA7: 2.94 | AB7: 145.79 | AC7: 40331 | AD7: 43.63 | AE7: 114.15 | AF7: 40679 | AG7: 7.65 | AH7: 136.85 | AI7: 40245 | AJ7: 91.02 | AK7: 118.4 | AL7: 40244 | AM7: 61.16 | AN7: 127.38 | AO7: 40331 | AP7: 36.45 | AQ7: 134.07 | AR7: 37726 | AS7: 24.16 | AT7: 140.49 | AU7: 37244 | AV7: 72.27 | AW7: 88.97 | AX7: 40331 | AY7: 62.6 | AZ7: 102.35 | BA7: 38453 | BB7: 11.06 | BC7: 130.32 | BD7: 40331 | BE7: 66.87 | BF7: 101.34 | BG7: 40287 | BH7: 33.79 | BI7: 137.21 | BJ7: 40331 | BK7: 34.07 | BL7: 140.93
A8: 40417 | B8: 34.55 | C8: 140.45 | E8: 40985 | F8: 10.19 | G8: 188.11 | H8: 41683 | I8: 16 | J8: 185 | K8: 41032 | L8: 8.67 | M8: 190.62 | N8: 40312 | O8: 71.76 | P8: 181.24 | Q8: 40498 | R8: 5.18 | S8: 164.96 | T8: 40498 | U8: 4.66 | V8: 165.37 | W8: 40857 | X8: 36.91 | Y8: 120.94 | Z8: 40899 | AA8: 3.24 | AB8: 145.76 | AC8: 40393 | AD8: 44.25 | AE8: 115.03 | AF8: 40745 | AG8: 7.69 | AH8: 136.78 | AI8: 40253 | AJ8: 91.06 | AK8: 118.22 | AL8: 40245 | AM8: 61.16 | AN8: 127.49 | AO8: 40394 | AP8: 36 | AQ8: 134.29 | AR8: 37732 | AS8: 24.01 | AT8: 140.64 | AU8: 37246 | AV8: 72.27 | AW8: 88.97 | AX8: 40393 | AY8: 63.08 | AZ8: 102.2 | BA8: 38462 | BB8: 11.28 | BC8: 130.1 | BD8: 40393 | BE8: 67.12 | BF8: 101.54 | BG8: 40351 | BH8: 33.75 | BI8: 137.25 | BJ8: 40417 | BK8: 34.55 | BL8: 140.45
A9: 40575 | B9: 34.65 | C9: 140.35 | E9: 41113 | F9: 10.11 | G9: 188.17 | H9: 41764 | I9: 15.26 | J9: 185.74 | K9: 41506 | L9: 11.48 | M9: 191.43 | N9: 40393 | O9: 71.9 | P9: 181.1 | Q9: 40777 | R9: 4.77 | S9: 165.55 | T9: 40777 | U9: 4.85 | V9: 165.14 | W9: 40934 | X9: 36.73 | Y9: 121.1 | Z9: 40934 | AA9: 3.11 | AB9: 146.13 | AC9: 40417 | AD9: 43.93 | AE9: 113.55 | AF9: 40777 | AG9: 7.65 | AH9: 136.81 | AI9: 40269 | AJ9: 91.14 | AK9: 118.37 | AL9: 40246 | AM9: 61.16 | AN9: 127.47 | AO9: 40417 | AP9: 36.12 | AQ9: 134.19 | AR9: 37734 | AS9: 24.19 | AT9: 140.46 | AU9: 37251 | AV9: 72.27 | AW9: 88.97 | AX9: 40403 | AY9: 63.1 | AZ9: 102.9 | BA9: 38467 | BB9: 11.4 | BC9: 129.98 | BD9: 40575 | BE9: 67.24 | BF9: 101.05 | BG9: 40305 | BH9: 34.29 | BI9: 136.71 | BJ9: 40575 | BK9: 34.65 | BL9: 140.35
A10: 40679 | B10: 34.57 | C10: 140.43 | E10: 41225 | F10: 10.13 | G10: 188.55 | H10: 41793 | I10: 16.12 | J10: 184.88 | K10: 41556 | L10: 12.83 | M10: 189.68 | N10: 40417 | O10: 71.9 | P10: 181.1 | Q10: 40814 | R10: 4.61 | S10: 164.98 | T10: 40814 | U10: 4.65 | V10: 165.01 | W10: 41025 | X10: 37.83 | Y10: 121.43 | Z10: 41025 | AA10: 3.05 | AB10: 145.98 | AC10: 40498 | AD10: 44.1 | AE10: 113.58 | AF10: 40800 | AG10: 7.68 | AH10: 137.01 | AI10: 40278 | AJ10: 91.19 | AK10: 118.22 | AL10: 40247 | AM10: 61.15 | AN10: 127.46 | AO10: 40498 | AP10: 35.44 | AQ10: 134.07 | AR10: 37735 | AS10: 24.18 | AT10: 140.47 | AU10: 37258 | AV10: 72.25 | AW10: 88.99 | AX10: 40575 | AY10: 62.92 | AZ10: 102.03 | BA10: 38474 | BB10: 11.32 | BC10: 130.06 | BD10: 40679 | BE10: 67.74 | BF10: 101.13 | BG10: 40393 | BH10: 33.84 | BI10: 137.16 | BJ10: 40679 | BK10: 34.57 | BL10: 140.43
A11: 40745 | B11: 34.54 | C11: 140.46 | E11: 41401 | F11: 10.16 | G11: 188.48 | H11: 41877 | I11: 16.89 | J11: 184.11 | K11: 41617 | L11: 10.13 | M11: 187.79 | N11: 40575 | O11: 71.52 | P11: 181.48 | Q11: 40834 | R11: 4.65 | S11: 164.88 | T11: 40834 | U11: 4.76 | V11: 165.25 | W11: 41059 | X11: 38.8 | Y11: 121.39 | Z11: 41059 | AA11: 2.84 | AB11: 145.96 | AC11: 40575 | AD11: 44.21 | AE11: 114.02 | AF11: 40814 | AG11: 7.7 | AH11: 136.88 | AI11: 40283 | AJ11: 91.22 | AK11: 118.09 | AL11: 40248 | AM11: 61.15 | AN11: 127.51 | AO11: 40575 | AP11: 34.75 | AQ11: 134.27 | AR11: 37746 | AS11: 24.01 | AT11: 140.64 | AU11: 37280 | AV11: 72.18 | AW11: 89.06 | AX11: 40679 | AY11: 62.9 | AZ11: 102.8 | BA11: 38524 | BB11: 11.4 | BC11: 129.98 | BD11: 40745 | BE11: 67.94 | BF11: 100.89 | BG11: 40417 | BH11: 33.9 | BI11: 137.1 | BJ11: 40745 | BK11: 34.54 | BL11: 140.46
A12: 40777 | B12: 34.39 | C12: 140.61 | E12: 41506 | F12: 10.34 | G12: 187.65 | H12: 41906 | I12: 17.21 | J12: 183.79 | K12: 41683 | L12: 11.6 | M12: 187.55 | N12: 40745 | O12: 71.59 | P12: 181.41 | Q12: 40911 | R12: 4.6 | S12: 164.97 | T12: 40911 | U12: 4.7 | V12: 165.55 | W12: 41072 | X12: 39.04 | Y12: 121.35 | Z12: 41072 | AA12: 2.8 | AB12: 146.08 | AC12: 40679 | AD12: 44.49 | AE12: 115.4 | AF12: 40834 | AG12: 7.7 | AH12: 137.14 | AI12: 40284 | AJ12: 91.2 | AK12: 118.35 | AL12: 40249 | AM12: 61.15 | AN12: 127.47 | AO12: 40679 | AP12: 34.79 | AQ12: 134.34 | AR12: 37748 | AS12: 23.95 | AT12: 140.7 | AU12: 37299 | AV12: 72.5 | AW12: 88.74 | AX12: 40679 | AY12: 62.9 | AZ12: 102.01 | BA12: 38538 | BB12: 11.2 | BC12: 130.18 | BD12: 40777 | BE12: 67.7 | BF12: 101.15 | BG12: 40575 | BH12: 33.53 | BI12: 137.47 | BJ12: 40777 | BK12: 34.39 | BL12: 140.61
A13: 40800 | B13: 34.1 | C13: 140.9 | E13: 41556 | F13: 9.42 | G13: 187.25 | H13: 41976 | I13: 15.16 | J13: 185.84 | K13: 41764 | L13: 10.38 | M13: 191.13 | N13: 40777 | O13: 71.7 | P13: 181.3 | Q13: 40967 | R13: 4.95 | S13: 165 | T13: 40967 | U13: 5.2 | V13: 165.55 | W13: 41171 | X13: 40.35 | Y13: 120.76 | Z13: 41171 | AA13: 2.63 | AB13: 146.04 | AC13: 40745 | AD13: 44.79 | AE13: 114.06 | AF13: 40911 | AG13: 6.75 | AH13: 137.2 | AI13: 40501 | AJ13: 92.19 | AK13: 118.28 | AL13: 40250 | AM13: 61.15 | AN13: 127.44 | AO13: 40745 | AP13: 34.49 | AQ13: 134.28 | AR13: 37749 | AS13: 23.93 | AT13: 140.72 | AU13: 37305 | AV13: 72.57 | AW13: 88.67 | AX13: 40745 | AY13: 63.09 | AZ13: 102.72 | BA13: 38596 | BB13: 11.36 | BC13: 130.02 | BD13: 40800 | BE13: 67.5 | BF13: 101 | BG13: 40679 | BH13: 34.29 | BI13: 136.71 | BJ13: 40800 | BK13: 34.1 | BL13: 140.9
A14: 40814 | B14: 34.19 | C14: 140.81 | E14: 41617 | F14: 9.55 | G14: 187.58 | H14: 42009 | I14: 16.17 | J14: 184.83 | K14: 41793 | L14: 9.57 | M14: 190.01 | N14: 40814 | O14: 71.64 | P14: 181.36 | Q14: 41011 | R14: 5.1 | S14: 164.88 | T14: 41011 | U14: 5.35 | V14: 165.55 | W14: 41228 | X14: 45.58 | Y14: 121.15 | Z14: 41235 | AA14: 2.78 | AB14: 145.68 | AC14: 40777 | AD14: 44.49 | AE14: 113.64 | AF14: 40934 | AG14: 6.94 | AH14: 137.15 | AI14: 40502 | AJ14: 92.2 | AK14: 118.36 | AL14: 40251 | AM14: 61.15 | AN14: 127.47 | AO14: 40777 | AP14: 34.39 | AQ14: 134.65 | AR14: 37750 | AS14: 23.96 | AT14: 140.69 | AU14: 37313 | AV14: 72.34 | AW14: 88.9 | AX14: 40777 | AY14: 63.45 | AZ14: 102.68 | BA14: 38592 | BB14: 11.41 | BC14: 129.97 | BD14: 40814 | BE14: 67.48 | BF14: 100.8 | BG14: 40745 | BH14: 34.39 | BI14: 136.61 | BJ14: 40814 | BK14: 34.19 | BL14: 140.81
A15: 40834 | B15: 34.15 | C15: 140.85 | E15: 41647 | F15: 9.46 | G15: 188.29 | H15: 42255 | I15: 14.3 | J15: 186.7 | K15: 41830 | L15: 11.32 | M15: 188.1 | N15: 40834 | O15: 71.55 | P15: 181.45 | Q15: 41072 | R15: 4.65 | S15: 165.04 | T15: 41072 | U15: 5.22 | V15: 165.47 | W15: 41235 | X15: 40.44 | Y15: 122.52 | Z15: 41278 | AA15: 3.16 | AB15: 145.91 | AC15: 40800 | AD15: 44.43 | AE15: 113.46 | AF15: 40963 | AG15: 7.34 | AH15: 137.43 | AI15: 40503 | AJ15: 92.2 | AK15: 117.93 | AL15: 40252 | AM15: 61.15 | AN15: 127.39 | AO15: 40800 | AP15: 34.27 | AQ15: 134.74 | AR15: 37755 | AS15: 24.09 | AT15: 140.56 | AU15: 37321 | AV15: 72.41 | AW15: 88.83 | AX15: 40800 | AY15: 63.46 | AZ15: 102.67 | BA15: 38629 | BB15: 11.35 | BC15: 130.03 | BD15: 40834 | BE15: 67.45 | BF15: 100.74 | BG15: 40777 | BH15: 34.49 | BI15: 136.51 | BJ15: 40834 | BK15: 34.15 | BL15: 140.85
... A23: 41278 | B23: 35.2 | C23: 139.8 | E23: 41976 | F23: 9.71 | G23: 186.34 | H23: 43122 | I23: 12.22 | J23: 188.78 | K23: 42292 | L23: 11.98 | M23: 189.73 | N23: 41235 | O23: 71.6 | P23: 181.4 | Q23: 41683 | R23: 4.91 | S23: 165.59 | T23: 41683 | U23: 5.26 | V23: 164.84 | W23: 41647 | X23: 41.1 | Y23: 121 | Z23: 41683 | AA23: 3.06 | AB23: 145.97 | AC23: 41059 | AD23: 43.95 | AE23: 114.64 | AF23: 42512 | AG23: 6.7 | AH23: 136.46 | AI23: 40542 | AJ23: 92.36 | AK23: 118.05 | AL23: 40260 | AM23: 61.16 | AN23: 128.68 | AO23: 41072 | AP23: 35.35 | AQ23: 133.77 | AR23: 37823 | AS23: 24.18 | AT23: 140.47 | AU23: 37396 | AV23: 72.27 | AW23: 88.97 | AX23: 41059 | AY23: 64.16 | AZ23: 103.69 | BA23: 38849 | BB23: 10.51 | BC23: 130.87 | BD23: 41098 | BE23: 68.25 | BF23: 101.64 | BG23: 41059 | BH23: 34.7 | BI23: 136.3 | BJ23: 41278 | BK23: 35.2 | BL23: 139.8
A24: 41401 | B24: 35.43 | C24: 139.57 | E24: 42009 | F24: 10.648333 | G24: 188.24 | K24: 42353 | L24: 12.32 | M24: 190.9 | N24: 41278 | O24: 71.67 | P24: 181.33 | Q24: 41744 | R24: 5.56 | S24: 165.58 | T24: 41744 | U24: 5.52 | V24: 164.88 | W24: 41683 | X24: 41.19 | Y24: 120.98 | Z24: 41731 | AA24: 3.31 | AB24: 146.44 | AC24: 41171 | AD24: 45.18 | AE24: 114.63 | AF24: 42702 | AG24: 6.58 | AH24: 136.5 | AI24: 40543 | AJ24: 92.39 | AK24: 118.03 | AL24: 40261 | AM24: 61.16 | AN24: 128.61 | AO24: 41191 | AP24: 35.62 | AQ24: 133.64 | AR24: 37831 | AS24: 24.2 | AT24: 140.45 | AU24: 37421 | AV24: 71.63 | AW24: 89.61 | AX24: 41072 | AY24: 63.24 | AZ24: 104.1 | BA24: 38909 | BB24: 11.03 | BC24: 130.35 | BD24: 41235 | BE24: 68.79 | BF24: 101.63 | BG24: 41073 | BH24: 34.64 | BI24: 136.36 | BJ24: 41401 | BK24: 35.43 | BL24: 139.57
A25: 41437 | B25: 35.5 | C25: 139.5 | E25: 42157 | F25: 10.55 | G25: 188.29 | K25: 42387 | L25: 13.47 | M25: 191.54 | N25: 41368 | O25: 71.88 | P25: 181.12 | Q25: 41764 | R25: 5.09 | S25: 165.55 | T25: 41764 | U25: 5.48 | V25: 164.92 | W25: 41731 | X25: 41.1 | Y25: 120.81 | Z25: 41764 | AA25: 2.96 | AB25: 146.02 | AC25: 41191 | AD25: 45.24 | AE25: 114.61 | AF25: 42865 | AG25: 5.83 | AH25: 136.44 | AI25: 40544 | AJ25: 92.4 | AK25: 118.02 | AL25: 40262 | AM25: 61.16 | AN25: 128.55 | AO25: 41228 | AP25: 35.75 | AQ25: 133.5 | AR25: 37839 | AS25: 24.22 | AT25: 140.43 | AU25: 37424 | AV25: 71.64 | AW25: 89.6 | AX25: 41098 | AY25: 64.35 | AZ25: 104.49 | BA25: 38960 | BB25: 11.27 | BC25: 130.11 | BD25: 41278 | BE25: 69.1 | BF25: 101.18 | BG25: 41228 | BH25: 34.57 | BI25: 136.43 | BJ25: 41437 | BK25: 35.5 | BL25: 139.5
A26: 41471 | B26: 35.58 | C26: 139.42 | E26: 42220 | F26: 11.2 | G26: 198 | K26: 42429 | L26: 13.02 | M26: 192.13 | N26: 41397 | O26: 71.82 | P26: 181.18 | Q26: 41793 | R26: 5.05 | S26: 165.4 | T26: 41793 | U26: 5.48 | V26: 164.63 | W26: 41764 | X26: 41.44 | Y26: 120.8 | Z26: 41793 | AA26: 2.94 | AB26: 146.01 | AC26: 41228 | AD26: 45.58 | AE26: 114.68 | AF26: 42887 | AG26: 6.9 | AH26: 136.43 | AI26: 40745 | AJ26: 91.55 | AK26: 117.99 | AL26: 40263 | AM26: 61.17 | AN26: 129.05 | AO26: 41278 | AP26: =(AP25+AP27)/2 -> 36.125 | AQ26: 133.43 | AR26: 37845 | AS26: 24.25 | AT26: 140.4 | AU26: 37431 | AV26: 71.64 | AW26: 89.6 | AX26: 41171 | AY26: 64.46 | AZ26: 104.74 | BA26: 38999 | BB26: 11.13 | BC26: 130.25 | BD26: 41368 | BE26: 69.45 | BF26: 100.99 | BG26: 41278 | BH26: 34.74 | BI26: 136.26 | BJ26: 41471 | BK26: 35.58 | BL26: 139.42
A27: 41506 | B27: 35.55 | C27: 139.45 | E27: 42255 | F27: 11.26 | G27: 198 | K27: 42471 | L27: 12.32 | M27: 193.89 | N27: 41437 | O27: 71.75 | P27: 181.25 | Q27: 42221 | R27: 5.89 | S27: 165.2 | T27: 42221 | U27: 5.73 | V27: 164.6 | W27: 41793 | X27: 41.56 | Y27: 120.77 | Z27: 41877 | AA27: 2.77 | AB27: 145.96 | AC27: 41235 | AD27: 45.41 | AE27: 114.64 | AF27: 43011 | AG27: 5.18 | AH27: 136.42 | AI27: 40777 | AJ27: 91.34 | AK27: 118.17 | AL27: 40264 | AM27: 61.17 | AN27: 129.02 | AO27: 41368 | AP27: 36.5 | AQ27: 133.22 | AR27: 37873 | AS27: 24.17 | AT27: 140.48 | AU27: 37440 | AV27: 71.73 | AW27: 89.51 | AX27: 41191 | AY27: 64.56 | AZ27: 104.67 | BA27: 39107 | BB27: 11.21 | BC27: 130.17 | BD27: 41401 | BE27: 69.22 | BF27: 100.86 | BG27: 41368 | BH27: 34.97 | BI27: 136.03 | BJ27: 41506 | BK27: 35.55 | BL27: 139.45
A28: 41617 | B28: 35.85 | C28: 139.15 | E28: 42292 | F28: 11.25 | G28: 198 | K28: 42557 | L28: 11.27 | M28: 194.51 | N28: 41471 | O28: 71.74 | P28: 181.26 | Q28: 42306 | R28: 5.36 | S28: 165.1 | T28: 42306 | U28: 5.38 | V28: 164.52 | W28: 41877 | X28: 41.96 | Y28: 120.75 | Z28: 41936 | AA28: 2.53 | AB28: 145.97 | AC28: 41278 | AD28: 45.76 | AE28: 114.83 | AF28: 43123 | AG28: 6.91 | AH28: 136.33 | AI28: 40814 | AJ28: 91.29 | AK28: 118.02 | AL28: 40265 | AM28: 61.16 | AN28: 128.82 | AO28: 41401 | AP28: 36.79 | AQ28: 133.38 | AR28: 37901 | AS28: 24.1 | AT28: 140.55 | AU28: 37448 | AV28: 71.94 | AW28: 89.3 | AX28: 41235 | AY28: 64.75 | AZ28: 104.05 | BA28: 39213 | BB28: 11.41 | BC28: 129.97 | BD28: 41437 | BE28: 69.79 | BF28: 100.79 | BG28: 41401 | BH28: 35.14 | BI28: 135.86 | BJ28: 41617 | BK28: 35.85 | BL28: 139.15
A29: 41647 | B29: 36.54 | C29: 138.46 | E29: 42353 | F29: 11.026 | G29: 198 | K29: 42591 | L29: 10.1 | M29: 194.93 | N29: 41506 | O29: 72.02 | P29: 180.98 | Q29: 42387 | R29: 5.78 | S29: 165.15 | T29: 42387 | U29: 5.61 | V29: 164.66 | W29: 41936 | X29: 42.11 | Y29: 120.74 | Z29: 42009 | AA29: 3 | AB29: 145.95 | AC29: 41368 | AD29: 46.02 | AE29: 113.83 | AF29: 43558 | AG29: 6.95 | AH29: 136.43 | AI29: 40834 | AJ29: 91.3 | AK29: 118.07 | AL29: 40266 | AM29: 61.15 | AN29: 128.8 | AO29: 41437 | AP29: 36.97 | AQ29: 133.32 | AR29: 37936 | AS29: 24.33 | AT29: 140.32 | AU29: 37453 | AV29: 72.03 | AW29: 89.21 | AX29: 41278 | AY29: 65 | AZ29: 104.03 | BA29: 39939 | BB29: 11.34 | BC29: 130.04 | BD29: 41471 | BE29: 69.91 | BF29: 100.82 | BG29: 41437 | BH29: 35.24 | BI29: 135.76 | BJ29: 41647 | BK29: 36.54 | BL29: 138.46
A30: 41683 | B30: 36.72 | C30: 138.28 | E30: 42429 | F30: 11.25 | G30: 188.18 | K30: 42858 | L30: 9.46 | M30: 195.54 | N30: 41555 | O30: 72.01 | P30: 180.99 | Q30: 42429 | R30: 5.63 | S30: 165.47 | T30: 42429 | U30: 5.67 | V30: 165.1 | W30: 42009 | X30: 42.1 | Y30: 120.4 | Z30: 42109 | AA30: 2.65 | AB30: 145.44 | AC30: 41401 | AD30: 46.12 | AE30: 113.93 | AF30: 44008 | AG30: 7.27 | AH30: 136.38 | AI30: 40864 | AJ30: 91.3 | AK30: 118.01 | AL30: 40267 | AM30: 61.16 | AN30: 128.81 | AO30: 41471 | AP30: 36.99 | AQ30: 133.49 | AR30: 37951 | AS30: 24.3 | AT30: 140.35 | AU30: 37459 | AV30: 72.1 | AW30: 89.14 | AX30: 41368 | AY30: 65.23 | AZ30: 103.87 | BA30: 40049 | BB30: 11.47 | BC30: 129.91 | BD30: 41506 | BE30: 69.9 | BF30: 100.76 | BG30: 41471 | BH30: 35.31 | BI30: 135.69 | BJ30: 41683 | BK30: 36.72 | BL30: 138.28
A31: 41764 | B31: 36.95 | C31: 138.05 | E31: 42471 | F31: 11.66 | G31: 198 | K31: 42888 | L31: 8.87 | M31: 195.37 | N31: 41556 | O31: 71.96 | P31: 181.04 | Q31: 42471 | R31: 5.77 | S31: 165.35 | T31: 42471 | U31: 6 | V31: 164.9 | W31: 42109 | X31: 42.37 | Y31: 120.4 | Z31: 42220 | AA31: 3.3 | AB31: 145.72 | AC31: 41437 | AD31: 46.37 | AE31: 113.98 | AF31: 43952 | AG31: 7.38 | AH31: 136.36 | AI31: 40889 | AJ31: 91.3 | AK31: 117.94 | AL31: 40268 | AM31: 61.17 | AN31: 128.96 | AO31: 41506 | AP31: 37.13 | AQ31: 133.34 | AR31: 37993 | AS31: 24.43 | AT31: 140.22 | AU31: 37466 | AV31: 72.28 | AW31: 88.96 | AX31: 41401 | AY31: 65.4 | AZ31: 103.85 | BA31: 40099 | BB31: 12.53 | BC31: 128.85 | BD31: 41555 | BE31: 70.2 | BF31: 100.64 | BG31: 41506 | BH31: 35.32 | BI31: 135.68 | BJ31: 41764 | BK31: 36.95 | BL31: 138.05
A32: 41793 | B32: 36.98 | C32: 138.02 | E32: 42557 | F32: 9.76 | K32: 43122 | L32: 7.11 | N32: 41617 | O32: 72.14 | P32: 180.86 | Q32: 42611 | R32: 5.63 | S32: 165.37 | T32: 42611 | U32: 6.68 | V32: 164.84 | W32: 42220 | X32: 42.51 | Y32: 119.55 | Z32: 42306 | AA32: 2.72 | AB32: 145.95 | AC32: 41471 | AD32: 46.57 | AE32: 113.98 | AF32: 44440 | AG32: 6.89 | AH32: 136.43 | AI32: 40911 | AJ32: 91.3 | AK32: 118 | AL32: 40269 | AM32: 61.17 | AN32: 128.86 | AO32: 41555 | AP32: 37.18 | AQ32: 133.3 | AR32: 38078 | AS32: 24.4 | AT32: 140.25 | AU32: 37474 | AV32: 72.08 | AW32: 89.16 | AX32: 41437 | AY32: 65.7 | AZ32: 103.79 | BA32: 40190 | BB32: 11.7 | BC32: 129.68 | BD32: 41556 | BE32: 70.17 | BF32: 101.1 | BG32: 41556 | BH32: 35.41 | BI32: 135.59 | BJ32: 41793 | BK32: 36.98 | BL32: 138.02
A33: 41830 | B33: 37.03 | C33: 137.97 | E33: 42591 | F33: 9.71 | K33: 43263 | L33: 6.49 | N33: 41647 | O33: 72.12 | P33: 180.88 | Q33: 42781 | R33: 5.86 | S33: 165.4 | T33: 42781 | U33: 6.96 | V33: 164.88 | W33: 42306 | X33: 42.79 | Y33: 120.61 | Z33: 42353 | AA33: 3.26 | AB33: 146.71 | AC33: 41506 | AD33: 46.46 | AE33: 113.96 | AF33: 44600 | AG33: 7.43 | AH33: 136.33 | AI33: 40967 | AJ33: 91.25 | AK33: 117.99 | AL33: 40270 | AM33: 61.17 | AN33: 128.85 | AO33: 41556 | AP33: 37.18 | AQ33: 132.7 | AR33: 38105 | AS33: 24.12 | AT33: 140.53 | AU33: 37480 | AV33: 72.1 | AW33: 89.14 | AX33: 41471 | AY33: 65.43 | AZ33: 104.54 | BA33: 40238 | BB33: 13 | BC33: 128.38 | BD33: 41617 | BE33: 70.57 | BF33: 101.07 | BG33: 41617 | BH33: 35.57 | BI33: 135.43 | BJ33: 41830 | BK33: 37.03 | BL33: 137.97
A34: 41976 | B34: 36.98 | C34: 138.02 | E34: 42768 | F34: 9.735 | K34: 43297 | L34: 6.07 | N34: 41683 | O34: 72.3 | P34: 180.7 | Q34: 42888 | R34: 5.92 | S34: 165.3 | T34: 42888 | U34: 5.33 | V34: 164.95 | W34: 42353 | X34: =(X33+X35)/2 -> 42.845 | Y34: 120.38 | Z34: 42387 | AA34: 3.36 | AB34: 146.85 | AC34: 41555 | AD34: 46.6 | AE34: 114.21 | AF34: 44845 | AG34: 8.63 | AH34: 137.03 | AI34: 41017 | AJ34: 91 | AK34: 118.05 | AL34: 40271 | AM34: 61.17 | AN34: 129.02 | AO34: 41617 | AP34: 37.15 | AQ34: 132.72 | AR34: 38117 | AS34: 24.1 | AT34: 140.55 | AU34: 37488 | AV34: 71.65 | AW34: 89.59 | AX34: 41506 | AY34: 65.42 | AZ34: 103.88 | BA34: 40777 | BB34: 10.43 | BC34: 130.95 | BD34: 41659 | BE34: 70.79 | BF34: 101.04 | BG34: 41647 | BH34: 35.72 | BI34: 135.28 | BJ34: 41976 | BK34: 36.98 | BL34: 138.02
A35: 42020 | B35: 38.76 | C35: 136.24 | E35: 42888 | F35: 9.7225 | K35: 43559 | L35: 5.46 | N35: 41764 | O35: 72.52 | P35: 180.48 | Q35: 43011 | R35: 5.4 | S35: 165.33 | T35: 43011 | U35: 4.71 | V35: 164.96 | W35: 42387 | X35: 42.9 | Y35: 120.33 | Z35: 42429 | AA35: 3.36 | AB35: 146.9 | AC35: 41556 | AD35: 46.57 | AE35: 114.28 | AF35: 45078 | AG35: 8.98 | AH35: 137.75 | AI35: 41072 | AJ35: 91.15 | AK35: 118.02 | AL35: 40272 | AM35: 61.17 | AN35: 128.92 | AO35: 41647 | AP35: 37.2 | AQ35: 132.7 | AR35: 38133 | AS35: 24.09 | AT35: 140.56 | AU35: 37494 | AV35: 71.53 | AW35: 89.71 | AX35: 41555 | AY35: 65.46 | AZ35: 103.92 | BA35: 41025 | BB35: 11 | BC35: 130.38 | BD35: 41683 | BE35: 71.01 | BF35: 100.91 | BG35: 41683 | BH35: 35.9 | BI35: 135.1 | BJ35: 42110 | BK35: 38.76 | BL35: 136.24
A36: 42099 | B36: 38.19 | C36: 136.81 | E36: 43177 | F36: 9.89 | K36: 43588 | L36: 5.63 | N36: 41793 | O36: 72.6 | P36: 180.4 | Q36: 43558 | R36: 5.58 | S36: 165.6 | T36: 43558 | U36: 5.85 | V36: 165 | W36: 42429 | X36: 42.98 | Y36: 120.44 | Z36: 42471 | AA36: 3.55 | AB36: 147.55 | AC36: 41617 | AD36: =(AD35+AD37)/2 -> 46.775 | AE36: 115.45 | AF36: 45177 | AG36: 7.9 | AH36: 136.95 | AI36: 41191 | AJ36: 91.34 | AK36: 118.01 | AL36: 40273 | AM36: 61.17 | AN36: 128.95 | AO36: 41683 | AP36: 37.24 | AQ36: 132.84 | AR36: 38161 | AS36: 24.17 | AT36: 140.48 | AU36: 37502 | AV36: 71.5 | AW36: 89.74 | AX36: 41556 | AY36: 65.58 | AZ36: 104.21 | BA36: 41235 | BB36: 10.94 | BC36: 130.44 | BD36: 41731 | BE36: 71.19 | BF36: 100.93 | BG36: 41731 | BH36: 35.92 | BI36: 135.08 | BJ36: 42009 | BK36: 38.19 | BL36: 136.81
A37: 42221 | B37: 39.17 | C37: 135.83 | E37: 43263 | F37: 9.98 | K37: 43711 | L37: =0.0257*(9^3) - 0.274*(9^2) - 0.0495*(9) + 9.249 -> 5.3448 | N37: 41830 | O37: 72.81 | P37: 180.19 | Q37: 43763 | R37: 6.18 | S37: 165.32 | T37: 43763 | U37: 6.4 | V37: 164.9 | W37: 42471 | X37: 43.27 | Y37: 120.35 | Z37: 42611 | AA37: 3.04 | AB37: 147.42 | AC37: 41647 | AD37: 46.98 | AE37: 115.27 | AF37: 45286 | AG37: 7.75 | AH37: 137.15 | AI37: 41235 | AJ37: 91.31 | AK37: 117.89 | AL37: 40274 | AM37: 61.18 | AN37: 128.9 | AO37: 41731 | AP37: 37.45 | AQ37: 132.75 | AR37: 38170 | AS37: 24.05 | AT37: 140.6 | AU37: 37510 | AV37: 71.54 | AW37: 89.7 | AX37: 41617 | AY37: 66.35 | AZ37: 104.64 | BA37: 41278 | BB37: 11.16 | BC37: 130.22 | BD37: 41647 | BE37: 70.79 | BF37: 100.94 | BG37: 41764 | BH37: 36.23 | BI37: 134.77 | BJ37: 42221 | BK37: 39.17 | BL37: 135.83
A38: 42353 | B38: 39.69 | C38: 135.31 | E38: 43409 | F38: 9.81 | K38: 43936 | L38: =0.0257*(9.01^3) - 0.274*(9^2) - 0.0495*(9) + 9.249 -> 5.4073204 | N38: 41877 | O38: 72.84 | P38: 180.16 | Q38: 43952 | R38: 5.49 | S38: 165.37 | T38: 43952 | U38: 5.6 | V38: 164.85 | W38: 42611 | X38: 43.65 | Y38: 120.04 | Z38: 42781 | AA38: 3.33 | AB38: 147.11 | AC38: 41683 | AD38: 47 | AE38: 115.23 | AF38: 45595 | AG38: 7.51 | AH38: 137.03 | AI38: 41278 | AJ38: 91.52 | AK38: 117.84 | AL38: 40275 | AM38: 61.18 | AN38: 128.9 | AO38: 41683 | AP38: 37.24 | AQ38: 132.66 | AR38: 38183 | AS38: 24.15 | AT38: 140.5 | AU38: 37515 | AV38: 71.46 | AW38: 89.78 | AX38: 41647 | AY38: 66.52 | AZ38: 104.46 | BA38: 41401 | BB38: 11.61 | BC38: 129.77 | BD38: 41683 | BE38: 71.01 | BF38: 100.97 | BG38: 41793 | BH38: 36.27 | BI38: 134.73 | BJ38: 42353 | BK38: 39.69 | BL38: 135.31
A39: 42387 | B39: 39.93 | C39: 135.07 | E39: 43559 | F39: 9.72875 | K39: 44112 | L39: =0.0257*(9.03^3) - 0.274*(9^2) - 0.0495*(9) + 9.249 -> 5.5327782 | N39: 41906 | O39: 73.01 | P39: 179.99 | Q39: 44087 | R39: 5.52 | S39: 165.42 | T39: 43964 | U39: 4.57 | V39: 164.75 | W39: 42781 | X39: 43.64 | Y39: 120.43 | Z39: 42794 | AA39: 3.06 | AB39: 147.07 | AC39: 41731 | AD39: 47.14 | AE39: 114.39 | AF39: 45633 | AG39: 7.78 | AH39: 136.99 | AI39: 41368 | AJ39: 91.88 | AK39: 117.87 | AL39: 40276 | AM39: 61.18 | AN39: 128.92 | AO39: 41731 | AP39: 37.45 | AQ39: 132.73 | AR39: 38197 | AS39: 24.17 | AT39: 140.48 | AU39: 37522 | AV39: 71.38 | AW39: 89.86 | AX39: 41683 | AY39: 66.75 | AZ39: 104.15 | BA39: 41438 | BB39: 11.56 | BC39: 129.82 | BD39: 41731 | BE39: 71.19 | BF39: 100.93 | BG39: 41830 | BH39: 36.41 | BI39: 134.59 | BJ39: 42387 | BK39: 39.93 | BL39: 135.07
A40: 42429 | B40: 40.42 | C40: 134.58 | E40: 43590 | F40: 9.82625 | K40: 44203 | L40: =0.0257*(9.04^3) - 0.274*(9^2) - 0.0495*(9) + 9.249 -> 5.5957159 | N40: 41936 | O40: 73.07 | P40: 179.93 | Q40: 44308 | R40: 5.47 | S40: 165.86 | T40: 44308 | U40: 4.44 | V40: 164.91 | W40: 42794 | X40: 43.45 | Y40: 120.31 | Z40: 42867 | AA40: 3.11 | AB40: 147.27 | AC40: 41764 | AD40: 47.34 | AE40: 114.35 | AF40: 45750 | AG40: 8.27 | AH40: 136.95 | AI40: 41401 | AJ40: 91.95 | AK40: 117.77 | AL40: 40277 | AM40: 61.18 | AN40: 129.02 | AO40: 41764 | AP40: 37.54 | AQ40: 133.03 | AR40: 38202 | AS40: 24.1 | AT40: 140.55 | AU40: 37530 | AV40: 71.43 | AW40: 89.81 | AX40: 41731 | AY40: 66.87 | AZ40: 104.28 | BA40: 41471 | BB40: 11.52 | BC40: 129.86 | BD40: 41764 | BE40: 71.39 | BF40: 100.83 | BG40: 41877 | BH40: 36.52 | BI40: 134.48 | BJ40: 42429 | BK40: 40.42 | BL40: 134.58
A41: 42471 | B41: 40.65 | C41: 134.35 | E41: 43559 | F41: 9.82 | K41: 44546 | L41: =0.0257*(9.09^3) - 0.274*(9^2) - 0.0495*(9) + 9.249 -> 5.9124983 | N41: 41976 | O41: 72.6 | P41: 180.4 | Q41: 44522 | R41: 5.88 | S41: 165.7 | T41: 44522 | U41: 4.78 | V41: 164.61 | W41: 43559 | X41: 44.47 | Y41: 120.18 | Z41: 43064 | AA41: 3.15 | AB41: 146.9 | AC41: 41793 | AD41: 47.32 | AE41: 114.33 | AF41: 45960 | AG41: 8.85 | AH41: 136.96 | AI41: 41432 | AJ41: 92.42 | AK41: 117.77 | AL41: 40278 | AM41: 61.18 | AN41: 128.97 | AO41: 41793 | AP41: 37.91 | AQ41: 133.18 | AR41: 38217 | AS41: 24.13 | AT41: 140.52 | AU41: 37537 | AV41: 71.43 | AW41: 89.81 | AX41: 41764 | AY41: 67.13 | AZ41: 103.92 | BA41: 41506 | BB41: 11.4 | BC41: 129.98 | BD41: 41793 | BE41: 71.52 | BF41: 100.79 | BG41: 41906 | BH41: 36.61 | BI41: 134.39 | BJ41: 42471 | BK41: 40.65 | BL41: 134.35
A42: 42591 | B42: 40.57 | C42: 134.43 | E42: 43588 | F42: 9.7916667 | K42: 44625 | L42: =0.0257*(9.099^3) - 0.274*(9^2) - 0.0495*(9) + 9.249 -> 5.9698908 | N42: 42009 | O42: 73.35 | P42: 179.65 | Q42: 44600 | R42: 5.95 | S42: 165.67 | T42: 44600 | U42: 4.82 | V42: 164.58 | W42: 43763 | X42: 53.37 | Y42: 120.13 | Z42: 43181 | AA42: 3.19 | AB42: 146.85 | AC42: 41830 | AD42: 47.47 | AE42: 114.23 | AF42: 46011 | AG42: 9.14 | AH42: 137.03 | AI42: 41471 | AJ42: 92.41 | AK42: 117.94 | AL42: 40279 | AM42: 61.18 | AN42: 129.14 | AO42: 41830 | AP42: 37.74 | AQ42: 133.53 | AR42: 38226 | AS42: 23.88 | AT42: 140.77 | AU42: 37545 | AV42: 71.51 | AW42: 89.73 | AX42: 41793 | AY42: 67.32 | AZ42: 103.79 | BA42: 41617 | BB42: 11.37 | BC42: 130.01 | BD42: 41830 | BE42: 71.75 | BF42: 100.84 | BG42: 41936 | BH42: 36.7 | BI42: 134.3 | BJ42: 42591 | BK42: 40.57 | BL42: 134.43
A43: 42702 | B43: 41.1 | C43: 133.9 | E43: 43905 | F43: 9.77 | K43: 44826 | L43: =0.0257*(9.11^3) - 0.274*(9^2) - 0.0495*(9) + 9.249 -> 6.0401914 | N43: 42157 | O43: 73.79 | P43: 179.21 | Q43: 44906 | R43: 5.77 | S43: 165.59 | T43: 44906 | U43: 4.97 | V43: 164.52 | W43: 43971 | X43: 45.17 | Y43: 119.57 | Z43: 43295 | AA43: 3.22 | AB43: 146.76 | AC43: 41877 | AD43: 47.52 | AE43: 114.13 | AF43: 38090 | AG43: 7.12 | AH43: 136.81 | AI43: 41506 | AJ43: 92.5 | AK43: 117.99 | AL43: 40280 | AM43: 61.18 | AN43: 128.99 | AO43: 41877 | AP43: 37.81 | AQ43: 133.32 | AR43: 38231 | AS43: 24.13 | AT43: 140.52 | AU43: 37551 | AV43: 71.51 | AW43: 89.73 | AX43: 41830 | AY43: 67.47 | AZ43: 103.62 | BA43: 41683 | BB43: 11.25 | BC43: 130.13 | BD43: 41936 | BE43: 72.27 | BF43: 100.75 | BG43: 41976 | BH43: 36.27 | BI43: 134.73 | BJ43: 42702 | BK43: 41.1 | BL43: 133.9
A44: 42774 | B44: 41.59 | C44: 133.41 | E44: 44100 | F44: 9.82 | K44: 44924 | L44: =0.0257*(9.103^3) - 0.274*(9^2) - 0.0495*(9) + 9.249 -> 5.995435 | N44: 42220 | O44: 74.05 | P44: 178.95 | Q44: 45078 | R44: 5.88 | S44: 165.44 | T44: 45078 | U44: 5.1 | V44: 164.38 | W44: 44087 | X44: 46.2 | Y44: 119.89 | Z44: 43445 | AA44: 3.17 | AB44: 146.74 | AC44: 41936 | AD44: 47.49 | AE44: 114.11 | AF44: 38107 | AG44: 6.97 | AH44: 136.96 | AI44: 41537 | AJ44: 92.81 | AK44: 117.63 | AL44: 40281 | AM44: 61.18 | AN44: 129.31 | AO44: 41906 | AP44: 37.95 | AQ44: 133.55 | AR44: 38237 | AS44: 24.13 | AT44: 140.52 | AU44: 37558 | AV44: 71.59 | AW44: 89.65 | AX44: 41877 | AY44: 67.69 | AZ44: 103.22 | BA44: 41764 | BB44: 11.32 | BC44: 130.06 | BD44: 41976 | BE44: 72.58 | BF44: 100.99 | BG44: 42009 | BH44: 36.97 | BI44: 134.03 | BJ44: 42774 | BK44: 41.59 | BL44: 133.41
A45: 42865 | B45: 41.79 | C45: 133.21 | E45: 44205 | F45: 9.912 | K45: 45088 | L45: =0.0257*(9.2^3) - 0.274*(9^2) - 0.0495*(9) + 9.249 -> 6.6217816 | N45: 42255 | O45: 74.17 | P45: 178.83 | Q45: 45268 | R45: 5.41 | S45: 165.38 | T45: 45268 | U45: 5.33 | V45: 164.37 | W45: 44308 | X45: 47 | Y45: 119.83 | Z45: 43559 | AA45: 3.23 | AB45: 146.79 | AC45: 41976 | AD45: 47.39 | AE45: 114.13 | AF45: 38124 | AG45: 6.92 | AH45: 137.01 | AI45: 41555 | AJ45: 92.76 | AK45: 117.72 | AL45: 40282 | AM45: 61.19 | AN45: 128.96 | AO45: 41936 | AP45: 37.82 | AQ45: 133.09 | AR45: 38246 | AS45: 24.22 | AT45: 140.43 | AU45: 37565 | AV45: 71.63 | AW45: 89.61 | AX45: 41906 | AY45: 67.9 | AZ45: 103.67 | BA45: 41976 | BB45: 11.22 | BC45: 130.16 | BD45: 42009 | BE45: 72.55 | BF45: 101.34 | BG45: 42107 | BH45: 37.14 | BI45: 133.86 | BJ45: 42865 | BK45: 41.79 | BL45: 133.21
A46: 42887 | B46: 41.93 | C46: 133.07 | E46: 44369 | F46: 9.873 | K46: 45238 | L46: =0.0257*(9.3^3) - 0.274*(9^2) - 0.0495*(9) + 9.249 -> 7.2814749 | N46: 42292 | O46: 74.28 | P46: 178.72 | Q46: 45595 | R46: 5.24 | S46: 165.3 | T46: 45595 | U46: 5.94 | V46: 164.34 | W46: 44522 | X46: 47.5 | Y46: 119.29 | Z46: 43763 | AA46: 3.38 | AB46: 146.74 | AC46: 42009 | AD46: 47.66 | AE46: 114.33 | AF46: 38133 | AG46: 6.82 | AH46: 137.11 | AI46: 41604 | AJ46: 93.1 | AK46: 117.67 | AL46: 40283 | AM46: 61.19 | AN46: 128.87 | AO46: 41976 | AP46: 37.77 | AQ46: 133.1 | AR46: 38251 | AS46: 24.09 | AT46: 140.56 | AU46: 37578 | AV46: 71.58 | AW46: 89.66 | AX46: 41936 | AY46: 67.71 | AZ46: 103.65 | BA46: 42471 | BB46: 13.39 | BC46: 127.99 | BD46: 42157 | BE46: 73.5 | BF46: 101.51 | BG46: 42157 | BH46: 37.22 | BI46: 133.78 | BJ46: 42887 | BK46: 41.93 | BL46: 133.07
A47: 42955 | B47: 41.8 | C47: 133.2 | E47: 44534 | F47: 9.72 | K47: 45349 | L47: =0.0257*(9.25^3) - 0.274*(9^2) - 0.0495*(9) + 9.249 -> 6.9498453 | N47: 42353 | O47: 74.49 | P47: 178.51 | Q47: 45787 | R47: 5.33 | S47: 165.25 | T47: 45787 | U47: 6.09 | V47: 164.35 | W47: 44600 | X47: 47.7 | Y47: 119.01 | Z47: 43971 | AA47: 3.1 | AB47: 146.9 | AC47: 42107 | AD47: 48.05 | AE47: 114.89 | AF47: 38153 | AG47: 6.57 | AH47: 137.36 | AI47: 41617 | AJ47: 93.15 | AK47: 117.66 | AL47: 40284 | AM47: 61.19 | AN47: 128.82 | AO47: 42009 | AP47: 37.65 | AQ47: 132.76 | AR47: 38265 | AS47: 24.1 | AT47: 140.55 | AU47: 37585 | AV47: 71.34 | AW47: 89.9 | AX47: 41976 | AY47: 68.06 | AZ47: 103.28 | BD47: 42220 | BE47: 73.82 | BF47: 101.68 | BG47: 42221 | BH47: 37.39 | BI47: 133.61 | BJ47: 42955 | BK47: 41.8 | BL47: 133.2
...

Sheet Niveles Imputados
A1: Sampues - # 52-II-C-PZ-01 | D1: Finca el socorro (Ovejas) - # 44-II-D-PO-02 | G1: Ovejas - # 44-II-D-PO-14 | J1: Los Palmitos - # 44-IV-B-PZ-01 Piñal | M1: Morroa (Bremen) - # 44-IV-C-PZ-01 A | P1: Bremen - # 44-IV-C-PZ-01 B | S1: Las Tinas (Morroa) - # 44-IV-C-PZ-02 A | V1: Las Tinas (Morroa) - # 44-IV-C-PZ-02 B | Y1: Arroyo salida a Betulia (Corozal) - # 44-IV-D-PZ-01 A | AB1: Arroyo salida a Betulia (Corozal) - # 44-IV-D-PZ-01 B | AE1: Sabanas de cali (El Tesoro) - # 44-IV-D-PZ-02 | AH1: Finca el tesoro - # 44-IV-D-PZ-04 | AK1: Basurero Viejo, Pileta (Corozal) - # 52-II-B-PZ-01 A | AN1: Corozal - # 44-IV-D-PO-14 | AQ1: Corozal - # 44-IV-D-PZ-20 | AT1: Corozal - # 44-IV-D-PZ-22 | AW1: Cantagallo - # 52-II-A-PZ-01 Corozal
A2: Fecha Medida | B2: Nivel Estático (m) | C2: Imputado | D2: Fecha Medida | E2: Nivel Estático (m) | F2: Imputado | G2: Fecha Medida | H2: Nivel Estático (m) | I2: Imputado | J2: Fecha Medida | K2: Nivel Estático (m) | L2: Imputado | M2: Fecha Medida | N2: Nivel Estático (m) | O2: Imputado | P2: Fecha Medida | Q2: Nivel Estático (m) | R2: Imputado | S2: Fecha Medida | T2: Nivel Estático (m) | U2: Imputado | V2: Fecha Medida | W2: Nivel Estático (m) | X2: Imputado | Y2: Fecha Medida | Z2: Nivel Estático (m) | AA2: Imputado | AB2: Fecha Medida | AC2: Nivel Estático (m) | AD2: imputado | AE2: Fecha Medida | AF2: Nivel Estático (m) | AG2: Imputado | AH2: Fecha Medida | AI2: Nivel Estático (m) | AJ2: Imputado | AK2: Fecha Medida | AL2: Nivel Estático (m) | AM2: Imputado | AN2: Fecha Medida | AO2: Nivel Estático (m) | AP2: Imputado | AQ2: Fecha Medida | AR2: Nivel Estático (m) | AS2: Imputado | AT2: Fecha Medida | AU2: Nivel Estático (m) | AV2: Imputado | AW2: Fecha Medida | AX2: Nivel Estático (m) | AY2: Imputado
A3: 40224 | B3: 34.45 | C3: 0 | D3: 40254 | E3: 10.27436 | F3: 0 | G3: 28/24/2010 | H3: 8.11 | I3: 0 | J3: 40224 | K3: 72.08 | L3: 0 | M3: 37635 | N3: 5 | O3: 0 | P3: 37635 | Q3: 4.45 | R3: 0 | S3: 37635 | T3: 28.58 | U3: 0 | V3: 37635 | W3: 3.13 | X3: 0 | Y3: 37657 | Z3: 30.9 | AA3: 0 | AB3: 37657 | AC3: 6.57 | AD3: 0 | AE3: 40190 | AF3: 89.7 | AG3: 0 | AH3: 40190 | AI3: 59.55 | AJ3: 0 | AK3: 40214 | AL3: 36.1 | AM3: 0 | AN3: 40214 | AO3: 61.48 | AP3: 0 | AQ3: 40190 | AR3: 11.7 | AS3: 0 | AT3: 40190 | AU3: 66.24 | AV3: 0 | AW3: 40214 | AX3: 34.17 | AY3: 0
A4: 40235 | B4: 34.98 | C4: 0 | D4: 40377 | E4: 10.22 | F4: 1 | G4: 40433 | H4: 8.34 | I4: 0 | J4: 40235 | K4: 72.5 | L4: 0 | M4: 37720 | N4: 5.03 | O4: 0 | P4: 37720 | Q4: 4.55 | R4: 0 | S4: 37720 | T4: 28.2 | U4: 0 | V4: 37720 | W4: 3.71 | X4: 0 | Y4: 37720 | Z4: 29.04 | AA4: 0 | AB4: 37720 | AC4: 6.84 | AD4: 0 | AE4: 40242 | AF4: 91.01 | AG4: 0 | AH4: 40238 | AI4: 60.06 | AJ4: 0 | AK4: 40235 | AL4: 36.3 | AM4: 0 | AN4: 40235 | AO4: 62.56 | AP4: 0 | AQ4: 40238 | AR4: 13 | AS4: 0 | AT4: 40235 | AU4: 66.9 | AV4: 0 | AW4: 40224 | AX4: 33.81 | AY4: 0
A5: 40287 | B5: 33.85 | C5: 0 | D5: 40531 | E5: 10.23 | F5: 0 | G5: 40636 | H5: 8.5 | I5: 1 | J5: 40242 | K5: 72.5 | L5: 0 | M5: 37726 | N5: 4.98 | O5: 0 | P5: 37726 | Q5: 4.61 | R5: 0 | S5: 37726 | T5: 28.3 | U5: 0 | V5: 37726 | W5: 3.23 | X5: 0 | Y5: 37726 | Z5: 30.75 | AA5: 0 | AB5: 37726 | AC5: 7.11 | AD5: 0 | AE5: 40244 | AF5: 91.02 | AG5: 0 | AH5: 40242 | AI5: 61.16 | AJ5: 0 | AK5: 40287 | AL5: 36.55 | AM5: 0 | AN5: 40287 | AO5: 62.5 | AP5: 0 | AQ5: 40490 | AR5: 11.57 | AS5: 1 | AT5: 40287 | AU5: 66.98 | AV5: 0 | AW5: 40235 | AX5: 34.2 | AY5: 0
A6: 40305 | B6: 34.87 | C6: 0 | D6: 40607 | E6: 10.232 | F6: 1 | G6: 40848 | H6: 8.79 | I6: 0 | J6: 40287 | K6: 71.98 | L6: 0 | M6: 37732 | N6: 5.1 | O6: 0 | P6: 37732 | Q6: 4.41 | R6: 0 | S6: 37732 | T6: 28.09 | U6: 0 | V6: 37732 | W6: 3.66 | X6: 0 | Y6: 37732 | Z6: 29.47 | AA6: 0 | AB6: 37732 | AC6: 6.85 | AD6: 0 | AE6: 40245 | AF6: 91.02 | AG6: 0 | AH6: 40243 | AI6: 61.14 | AJ6: 0 | AK6: 40305 | AL6: 36.36 | AM6: 0 | AN6: 40305 | AO6: 62.34 | AP6: 0 | AQ6: 40777 | AR6: 10.43 | AS6: 0 | AT6: 40305 | AU6: 66.81 | AV6: 0 | AW6: 40242 | AX6: 34.8 | AY6: 0
A7: 40331 | B7: 34.07 | C7: 0 | D7: 40766 | E7: 10.2 | F7: 0 | G7: 40953 | H7: 8.63 | I7: 1 | J7: 40331 | K7: 71.78 | L7: 0 | M7: 37734 | N7: 5.06 | O7: 0 | P7: 37734 | Q7: 4.6 | R7: 0 | S7: 37734 | T7: 28.42 | U7: 0 | V7: 37734 | W7: 3.66 | X7: 0 | Y7: 37734 | Z7: 29.78 | AA7: 0 | AB7: 37734 | AC7: 7.08 | AD7: 0 | AE7: 40253 | AF7: 91.06 | AG7: 0 | AH7: 40244 | AI7: 61.16 | AJ7: 0 | AK7: 40331 | AL7: 36.45 | AM7: 0 | AN7: 40331 | AO7: 62.6 | AP7: 0 | AQ7: 40890 | AR7: 10.27 | AS7: 0 | AT7: 40331 | AU7: 66.87 | AV7: 0 | AW7: 40287 | AX7: 33.79 | AY7: 0
A8: 40417 | B8: 34.55 | C8: 0 | D8: 40985 | E8: 10.19 | F8: 0 | G8: 41032 | H8: 8.67 | I8: 0 | J8: 40312 | K8: 71.76 | L8: 0 | M8: 37735 | N8: 5.04 | O8: 0 | P8: 37735 | Q8: 4.63 | R8: 0 | S8: 37735 | T8: 28.51 | U8: 0 | V8: 37735 | W8: 3.69 | X8: 0 | Y8: 37735 | Z8: 28.9 | AA8: 0 | AB8: 37735 | AC8: 7.15 | AD8: 0 | AE8: 40269 | AF8: 91.14 | AG8: 0 | AH8: 40245 | AI8: 61.16 | AJ8: 0 | AK8: 40394 | AL8: 36 | AM8: 0 | AN8: 40393 | AO8: 63.08 | AP8: 0 | AQ8: 40922 | AR8: 10.77 | AS8: 1 | AT8: 40393 | AU8: 67.12 | AV8: 0 | AW8: 40351 | AX8: 33.75 | AY8: 0
A9: 40575 | B9: 34.65 | C9: 0 | D9: 41113 | E9: 10.11 | F9: 0 | G9: 41506 | H9: 11.48 | I9: 0 | J9: 40393 | K9: 71.9 | L9: 0 | M9: 37746 | N9: 4.45 | O9: 0 | P9: 37746 | Q9: 4.86 | R9: 0 | S9: 37746 | T9: 28.35 | U9: 0 | V9: 37746 | W9: 3.32 | X9: 0 | Y9: 37746 | Z9: 30.38 | AA9: 0 | AB9: 37746 | AC9: 7.12 | AD9: 0 | AE9: 40278 | AF9: 91.19 | AG9: 0 | AH9: 40246 | AI9: 61.16 | AJ9: 0 | AK9: 40417 | AL9: 36.12 | AM9: 0 | AN9: 40403 | AO9: 63.1 | AP9: 0 | AQ9: 41025 | AR9: 11 | AS9: 0 | AT9: 40575 | AU9: 67.24 | AV9: 0 | AW9: 40305 | AX9: 34.29 | AY9: 0
A10: 40679 | B10: 34.57 | C10: 0 | D10: 41225 | E10: 10.13 | F10: 1 | G10: 41556 | H10: 12.83 | I10: 0 | J10: 40417 | K10: 71.9 | L10: 0 | M10: 37749 | N10: 5.02 | O10: 0 | P10: 37749 | Q10: 4.99 | R10: 0 | S10: 37748 | T10: 28.02 | U10: 0 | V10: 37748 | W10: 3.47 | X10: 0 | Y10: 37748 | Z10: 30.35 | AA10: 0 | AB10: 37748 | AC10: 6.92 | AD10: 0 | AE10: 40283 | AF10: 91.22 | AG10: 0 | AH10: 40247 | AI10: 61.15 | AJ10: 0 | AK10: 40498 | AL10: 35.44 | AM10: 0 | AN10: 40575 | AO10: 62.92 | AP10: 0 | AQ10: 41235 | AR10: 10.94 | AS10: 0 | AT10: 40679 | AU10: 67.74 | AV10: 0 | AW10: 40393 | AX10: 33.84 | AY10: 0
A11: 40745 | B11: 34.54 | C11: 0 | D11: 41401 | E11: 10.16 | F11: 0 | G11: 41617 | H11: 10.13 | I11: 0 | J11: 40575 | K11: 71.52 | L11: 0 | M11: 37750 | N11: 5.12 | O11: 0 | P11: 37750 | Q11: 4.75 | R11: 0 | S11: 37749 | T11: 28.06 | U11: 0 | V11: 37749 | W11: 3.49 | X11: 0 | Y11: 37749 | Z11: 29.91 | AA11: 0 | AB11: 37749 | AC11: 7.05 | AD11: 0 | AE11: 40284 | AF11: 91.2 | AG11: 0 | AH11: 40248 | AI11: 61.15 | AJ11: 0 | AK11: 40575 | AL11: 34.75 | AM11: 0 | AN11: 40679 | AO11: 62.9 | AP11: 0 | AQ11: 41278 | AR11: 11.16 | AS11: 0 | AT11: 40745 | AU11: 67.94 | AV11: 0 | AW11: 40417 | AX11: 33.9 | AY11: 0
A12: 40777 | B12: 34.39 | C12: 0 | D12: 41506 | E12: 10.34 | F12: 0 | G12: 41683 | H12: 11.6 | I12: 0 | J12: 40745 | K12: 71.59 | L12: 0 | M12: 37755 | N12: 5.03 | O12: 0 | P12: 37755 | Q12: 4.45 | R12: 0 | S12: 37750 | T12: 28.1 | U12: 0 | V12: 37750 | W12: 3.37 | X12: 0 | Y12: 37750 | Z12: 28.53 | AA12: 0 | AB12: 37750 | AC12: 6.79 | AD12: 0 | AE12: 40501 | AF12: 92.19 | AG12: 0 | AH12: 40249 | AI12: 61.15 | AJ12: 0 | AK12: 40679 | AL12: 34.79 | AM12: 0 | AN12: 40679 | AO12: 62.9 | AP12: 0 | AQ12: 41401 | AR12: 11.61 | AS12: 0 | AT12: 40777 | AU12: 67.7 | AV12: 0 | AW12: 40575 | AX12: 33.53 | AY12: 0
A13: 40800 | B13: 34.1 | C13: 0 | D13: 41556 | E13: 9.42 | F13: 0 | G13: 41764 | H13: 10.38 | I13: 0 | J13: 40777 | K13: 71.7 | L13: 0 | M13: 37758 | N13: 5 | O13: 0 | P13: 37758 | Q13: 4.45 | R13: 0 | S13: 37755 | T13: 28.69 | U13: 0 | V13: 37755 | W13: 3.41 | X13: 0 | Y13: 37755 | Z13: 29.87 | AA13: 0 | AB13: 37755 | AC13: 6.73 | AD13: 0 | AE13: 40502 | AF13: 92.2 | AG13: 0 | AH13: 40250 | AI13: 61.15 | AJ13: 0 | AK13: 40745 | AL13: 34.49 | AM13: 0 | AN13: 40745 | AO13: 63.09 | AP13: 0 | AQ13: 41438 | AR13: 11.56 | AS13: 0 | AT13: 40800 | AU13: 67.5 | AV13: 0 | AW13: 40679 | AX13: 34.29 | AY13: 0
A14: 40814 | B14: 34.19 | C14: 0 | D14: 41617 | E14: 9.55 | F14: 0 | G14: 41793 | H14: 9.57 | I14: 0 | J14: 40814 | K14: 71.64 | L14: 0 | M14: 37768 | N14: 5.12 | O14: 0 | P14: 37768 | Q14: 4.45 | R14: 0 | S14: 37758 | T14: 28.3 | U14: 0 | V14: 37758 | W14: 3.77 | X14: 0 | Y14: 37758 | Z14: 30.29 | AA14: 0 | AB14: 37758 | AC14: 6.78 | AD14: 0 | AE14: 40503 | AF14: 92.2 | AG14: 0 | AH14: 40251 | AI14: 61.15 | AJ14: 0 | AK14: 40777 | AL14: 34.39 | AM14: 0 | AN14: 40777 | AO14: 63.45 | AP14: 0 | AQ14: 41471 | AR14: 11.52 | AS14: 0 | AT14: 40814 | AU14: 67.48 | AV14: 0 | AW14: 40745 | AX14: 34.39 | AY14: 0
A15: 40834 | B15: 34.15 | C15: 0 | D15: 41647 | E15: 9.46 | F15: 0 | G15: 41830 | H15: 11.32 | I15: 0 | J15: 40834 | K15: 71.55 | L15: 0 | M15: 37797 | N15: 4.96 | O15: 0 | P15: 37797 | Q15: 4.53 | R15: 0 | S15: 37768 | T15: 26.93 | U15: 0 | V15: 37768 | W15: 3.54 | X15: 0 | Y15: 37768 | Z15: 30.47 | AA15: 0 | AB15: 37768 | AC15: 6.5 | AD15: 0 | AE15: 40504 | AF15: 92.2 | AG15: 0 | AH15: 40252 | AI15: 61.15 | AJ15: 0 | AK15: 40800 | AL15: 34.27 | AM15: 0 | AN15: 40800 | AO15: 63.46 | AP15: 0 | AQ15: 41506 | AR15: 11.4 | AS15: 0 | AT15: 40834 | AU15: 67.45 | AV15: 0 | AW15: 40777 | AX15: 34.49 | AY15: 0
... A25: 41437 | B25: 35.5 | C25: 0 | D25: 42157 | E25: 10.55 | F25: 0 | G25: 42387 | H25: 13.47 | I25: 0 | J25: 41368 | K25: 71.88 | L25: 0 | M25: 38050 | N25: 4.45 | O25: 0 | P25: 38050 | Q25: 5.08 | R25: 0 | S25: 38009 | T25: 28.64 | U25: 0 | V25: 38009 | W25: 3.43 | X25: 0 | Y25: 37845 | Z25: 29.32 | AA25: 0 | AB25: 37845 | AC25: 7.49 | AD25: 0 | AE25: 40745 | AF25: 91.55 | AG25: 0 | AH25: 40262 | AI25: 61.16 | AJ25: 0 | AK25: 41228 | AL25: 35.75 | AM25: 0 | AN25: 41098 | AO25: 64.35 | AP25: 0 | AQ25: 42733 | AR25: 14.96 | AS25: 0 | AT25: 41278 | AU25: 69.1 | AV25: 0 | AW25: 41228 | AX25: 34.57 | AY25: 0
A26: 41471 | B26: 35.58 | C26: 0 | D26: 42220 | E26: 11.2 | F26: 0 | G26: 42429 | H26: 13.02 | I26: 0 | J26: 41397 | K26: 71.82 | L26: 0 | M26: 43588 | N26: 4.6 | O26: 0 | P26: 43588 | Q26: 5.37 | R26: 0 | S26: 38110 | T26: 28.65 | U26: 0 | V26: 38110 | W26: 3.44 | X26: 0 | Y26: 37744 | Z26: 29.25 | AA26: 0 | AB26: 37744 | AC26: 7.5 | AD26: 0 | AE26: 40777 | AF26: 91.34 | AG26: 0 | AH26: 40263 | AI26: 61.17 | AJ26: 0 | AK26: 41278 | AL26: =(AL25+AL27)/2 -> 36.125 | AM26: 0 | AN26: 41171 | AO26: 64.46 | AP26: 0 | AQ26: Total | AR26: =COUNT(AR3:AR25) -> 23 | AS26: =SUM(AS3:AS25) -> 4 | AT26: 41368 | AU26: 69.45 | AV26: 0 | AW26: 41278 | AX26: 34.74 | AY26: 0
A27: 41506 | B27: 35.55 | C27: 0 | D27: 42255 | E27: 11.26 | F27: 0 | G27: 42471 | H27: 12.32 | I27: 0 | J27: 41437 | K27: 71.75 | L27: 0 | M27: 38078 | N27: 4.8 | O27: 0 | P27: 38078 | Q27: 5.4 | R27: 0 | S27: 38048 | T27: 28.68 | U27: 0 | V27: 38048 | W27: 3.49 | X27: 0 | Y27: 37858 | Z27: 29.29 | AA27: 0 | AB27: 37858 | AC27: 7.51 | AD27: 0 | AE27: 40814 | AF27: 91.29 | AG27: 0 | AH27: 40264 | AI27: 61.17 | AJ27: 0 | AK27: 41368 | AL27: 36.5 | AM27: 0 | AN27: 41191 | AO27: 64.56 | AP27: 0 | AT27: 41401 | AU27: 69.22 | AV27: 0 | AW27: 41368 | AX27: 34.97 | AY27: 0
A28: 41617 | B28: 35.85 | C28: 0 | D28: 42292 | E28: 11.25 | F28: 0 | G28: 42557 | H28: 11.27 | I28: 0 | J28: 41471 | K28: 71.74 | L28: 0 | M28: 38090 | N28: 4.9 | O28: 0 | P28: 38090 | Q28: 5.48 | R28: 0 | S28: 38058 | T28: 28.7 | U28: 0 | V28: 38058 | W28: 3.48 | X28: 0 | Y28: 37865 | Z28: 29.1 | AA28: 0 | AB28: 37865 | AC28: 7.6 | AD28: 0 | AE28: 40834 | AF28: 91.3 | AG28: 0 | AH28: 40265 | AI28: 61.16 | AJ28: 0 | AK28: 41401 | AL28: 36.79 | AM28: 0 | AN28: 41235 | AO28: 64.75 | AP28: 0 | AT28: 41437 | AU28: 69.79 | AV28: 0 | AW28: 41401 | AX28: 35.14 | AY28: 0
A29: 41647 | B29: 36.54 | C29: 0 | D29: 42353 | E29: 11.026 | F29: 0 | G29: 42591 | H29: 10.1 | I29: 0 | J29: 41506 | K29: 72.02 | L29: 0 | M29: 38105 | N29: 4.85 | O29: 0 | P29: 38105 | Q29: 5.34 | R29: 0 | S29: 38078 | T29: 28.71 | U29: 0 | V29: 38078 | W29: 3.5 | X29: 0 | Y29: 37872 | Z29: 30.1 | AA29: 0 | AB29: 37872 | AC29: 7.5 | AD29: 0 | AE29: 40864 | AF29: 91.3 | AG29: 0 | AH29: 40266 | AI29: 61.15 | AJ29: 0 | AK29: 41437 | AL29: 36.97 | AM29: 0 | AN29: 41278 | AO29: 65 | AP29: 0 | AT29: 41471 | AU29: 69.91 | AV29: 0 | AW29: 41437 | AX29: 35.24 | AY29: 0
A30: 41683 | B30: 36.72 | C30: 0 | D30: 42429 | E30: 11.25 | F30: 0 | G30: 42858 | H30: 9.46 | I30: 0 | J30: 41555 | K30: 72.01 | L30: 0 | M30: 38133 | N30: 4.53 | O30: 0 | P30: 38133 | Q30: 4.9 | R30: 0 | S30: 38090 | T30: 29.05 | U30: 0 | V30: 38090 | W30: 4.01 | X30: 0 | Y30: 37873 | Z30: 30 | AA30: 0 | AB30: 37873 | AC30: 7.55 | AD30: 0 | AE30: 40889 | AF30: 91.3 | AG30: 0 | AH30: 40267 | AI30: 61.16 | AJ30: 0 | AK30: 41471 | AL30: 36.99 | AM30: 0 | AN30: 41368 | AO30: 65.23 | AP30: 0 | AT30: 41506 | AU30: 69.9 | AV30: 0 | AW30: 41471 | AX30: 35.31 | AY30: 0
A31: 41764 | B31: 36.95 | C31: 0 | D31: 42471 | E31: 11.66 | F31: 0 | G31: 42888 | H31: 8.87 | I31: 0 | J31: 41556 | K31: 71.96 | L31: 0 | M31: 38155 | N31: 4.65 | O31: 0 | P31: 38155 | Q31: 5.1 | R31: 0 | S31: 38105 | T31: 29.05 | U31: 0 | V31: 38105 | W31: 3.73 | X31: 0 | Y31: 37881 | Z31: 29.95 | AA31: 0 | AB31: 37881 | AC31: 7.57 | AD31: 0 | AE31: 40911 | AF31: 91.3 | AG31: 0 | AH31: 40268 | AI31: 61.17 | AJ31: 0 | AK31: 41506 | AL31: 37.13 | AM31: 0 | AN31: 41401 | AO31: 65.4 | AP31: 0 | AT31: 41555 | AU31: 70.2 | AV31: 0 | AW31: 41506 | AX31: 35.32 | AY31: 0
A32: 41793 | B32: 36.98 | C32: 0 | D32: 42557 | E32: 9.76 | F32: 0 | G32: 43122 | H32: 7.11 | I32: 0 | J32: 41617 | K32: 72.14 | L32: 0 | M32: 38161 | N32: 4.63 | O32: 0 | P32: 38161 | Q32: 5.16 | R32: 0 | S32: 38117 | T32: 29.9 | U32: 0 | V32: 38117 | W32: 3.5 | X32: 0 | Y32: 37895 | Z32: 29.95 | AA32: 0 | AB32: 37895 | AC32: 7.5 | AD32: 0 | AE32: 40967 | AF32: 91.25 | AG32: 0 | AH32: 40269 | AI32: 61.17 | AJ32: 0 | AK32: 41555 | AL32: 37.18 | AM32: 0 | AN32: 41437 | AO32: 65.7 | AP32: 0 | AT32: 41556 | AU32: 70.17 | AV32: 0 | AW32: 41556 | AX32: 35.41 | AY32: 0
A33: 41830 | B33: 37.03 | C33: 0 | D33: 42591 | E33: 9.71 | F33: 0 | G33: 43263 | H33: 6.49 | I33: 0 | J33: 41647 | K33: 72.12 | L33: 0 | M33: 38170 | N33: 4.6 | O33: 0 | P33: 38170 | Q33: 5.12 | R33: 0 | S33: 38161 | T33: 28.84 | U33: 0 | V33: 38161 | W33: 2.74 | X33: 0 | Y33: 37900 | Z33: 29.97 | AA33: 0 | AB33: 37900 | AC33: 7.6 | AD33: 0 | AE33: 41017 | AF33: 91 | AG33: 0 | AH33: 40270 | AI33: 61.17 | AJ33: 0 | AK33: 41556 | AL33: 37.18 | AM33: 0 | AN33: 41471 | AO33: 65.43 | AP33: 0 | AT33: 41617 | AU33: 70.57 | AV33: 0 | AW33: 41617 | AX33: 35.57 | AY33: 0
A34: 41976 | B34: 36.98 | C34: 0 | D34: 42768 | E34: 9.735 | F34: 0 | G34: 43297 | H34: 6.07 | I34: 0 | J34: 41683 | K34: 72.3 | L34: 0 | M34: 38197 | N34: 4.7 | O34: 0 | P34: 38197 | Q34: 5.05 | R34: 0 | S34: 38189 | T34: 29.07 | U34: 0 | V34: 38189 | W34: 2.6 | X34: 0 | Y34: 37937 | Z34: 29.72 | AA34: 0 | AB34: 37937 | AC34: 6.9 | AD34: 0 | AE34: 41072 | AF34: 91.15 | AG34: 0 | AH34: 40271 | AI34: 61.17 | AJ34: 0 | AK34: 41617 | AL34: 37.15 | AM34: 0 | AN34: 41506 | AO34: 65.42 | AP34: 0 | AT34: 41659 | AU34: 70.79 | AV34: 0 | AW34: 41647 | AX34: 35.72 | AY34: 0
A35: 42020 | B35: 38.76 | C35: 0 | D35: 42888 | E35: 9.7225 | F35: 0 | G35: 43559 | H35: 5.46 | I35: 0 | J35: 41764 | K35: 72.52 | L35: 0 | M35: 38203 | N35: 4.67 | O35: 0 | P35: 38203 | Q35: 5.04 | R35: 0 | S35: 38197 | T35: 29.12 | U35: 0 | V35: 38197 | W35: 2.55 | X35: 0 | Y35: 37952 | Z35: 29.65 | AA35: 0 | AB35: 37952 | AC35: 6.18 | AD35: 0 | AE35: 41191 | AF35: 91.34 | AG35: 0 | AH35: 40272 | AI35: 61.17 | AJ35: 0 | AK35: 41647 | AL35: 37.2 | AM35: 0 | AN35: 41555 | AO35: 65.46 | AP35: 0 | AT35: 41683 | AU35: 71.01 | AV35: 0 | AW35: 41683 | AX35: 35.9 | AY35: 0
A36: 42099 | B36: 38.19 | C36: 0 | D36: 43177 | E36: 9.89 | F36: 1 | G36: 43588 | H36: 5.63 | I36: 0 | J36: 41793 | K36: 72.6 | L36: 0 | M36: 38209 | N36: 4.4 | O36: 0 | P36: 38209 | Q36: 5 | R36: 0 | S36: 38203 | T36: 29.01 | U36: 0 | V36: 38203 | W36: 1.9 | X36: 0 | Y36: 37993 | Z36: 28.48 | AA36: 0 | AB36: 37993 | AC36: 6.98 | AD36: 0 | AE36: 41235 | AF36: 91.31 | AG36: 0 | AH36: 40273 | AI36: 61.17 | AJ36: 0 | AK36: 41683 | AL36: 37.24 | AM36: 0 | AN36: 41556 | AO36: 65.58 | AP36: 0 | AT36: 41731 | AU36: 71.19 | AV36: 0 | AW36: 41731 | AX36: 35.92 | AY36: 0
A37: 42221 | B37: 39.17 | C37: 0 | D37: 43263 | E37: 9.98 | F37: 0 | G37: 43711 | H37: =0.0257*(9^3) - 0.274*(9^2) - 0.0495*(9) + 9.249 -> 5.3448 | I37: 1 | J37: 41830 | K37: 72.81 | L37: 0 | M37: 38217 | N37: 4.68 | O37: 0 | P37: 38217 | Q37: 5.1 | R37: 0 | S37: 38217 | T37: 29.1 | U37: 0 | V37: 38217 | W37: 2.03 | X37: 0 | Y37: 38000 | Z37: 28.66 | AA37: 0 | AB37: 38000 | AC37: 6.78 | AD37: 0 | AE37: 41278 | AF37: 91.52 | AG37: 0 | AH37: 40274 | AI37: 61.18 | AJ37: 0 | AK37: 41731 | AL37: 37.45 | AM37: 0 | AN37: 41617 | AO37: 66.35 | AP37: 0 | AT37: 41647 | AU37: 70.79 | AV37: 0 | AW37: 41764 | AX37: 36.23 | AY37: 0
A38: 42353 | B38: 39.69 | C38: 0 | D38: 43409 | E38: 9.81 | F38: 1 | G38: 43936 | H38: =0.0257*(9.01^3) - 0.274*(9^2) - 0.0495*(9) + 9.249 -> 5.4073204 | I38: 0 | J38: 41877 | K38: 72.84 | L38: 0 | M38: 38230 | N38: 4.63 | O38: 0 | P38: 38230 | Q38: 5.15 | R38: 0 | S38: 38231 | T38: 29.41 | U38: 0 | V38: 38231 | W38: 2.34 | X38: 0 | Y38: 38009 | Z38: 28.7 | AA38: 0 | AB38: 38009 | AC38: 6.9 | AD38: 0 | AE38: 41368 | AF38: 91.88 | AG38: 0 | AH38: 40275 | AI38: 61.18 | AJ38: 0 | AK38: 41683 | AL38: 37.24 | AM38: 0 | AN38: 41647 | AO38: 66.52 | AP38: 0 | AT38: 41683 | AU38: 71.01 | AV38: 0 | AW38: 41793 | AX38: 36.27 | AY38: 0
A39: 42387 | B39: 39.93 | C39: 0 | D39: 43559 | E39: 9.72875 | F39: 0 | G39: 44112 | H39: =0.0257*(9.03^3) - 0.274*(9^2) - 0.0495*(9) + 9.249 -> 5.5327782 | I39: 0 | J39: 41906 | K39: 73.01 | L39: 0 | M39: 38286 | N39: 4.58 | O39: 0 | P39: 38286 | Q39: 5.25 | R39: 0 | S39: 38286 | T39: 29.02 | U39: 0 | V39: 38286 | W39: 2.38 | X39: 0 | Y39: 38049 | Z39: 29.54 | AA39: 0 | AB39: 38049 | AC39: 6.94 | AD39: 0 | AE39: 41401 | AF39: 91.95 | AG39: 0 | AH39: 40276 | AI39: 61.18 | AJ39: 0 | AK39: 41731 | AL39: 37.45 | AM39: 0 | AN39: 41683 | AO39: 66.75 | AP39: 0 | AT39: 41731 | AU39: 71.19 | AV39: 0 | AW39: 41830 | AX39: 36.41 | AY39: 0
A40: 42429 | B40: 40.42 | C40: 0 | D40: 43590 | E40: 9.82625 | F40: 0 | G40: 44203 | H40: =0.0257*(9.04^3) - 0.274*(9^2) - 0.0495*(9) + 9.249 -> 5.5957159 | I40: 1 | J40: 41936 | K40: 73.07 | L40: 0 | M40: 38313 | N40: 4.14 | O40: 0 | P40: 38313 | Q40: 5.09 | R40: 0 | S40: 38308 | T40: 29.14 | U40: 0 | V40: 38308 | W40: 2.18 | X40: 0 | Y40: 38061 | Z40: 29.58 | AA40: 0 | AB40: 38061 | AC40: 6.98 | AD40: 0 | AE40: 41432 | AF40: 92.42 | AG40: 0 | AH40: 40277 | AI40: 61.18 | AJ40: 0 | AK40: 41764 | AL40: 37.54 | AM40: 0 | AN40: 41731 | AO40: 66.87 | AP40: 0 | AT40: 41764 | AU40: 71.39 | AV40: 0 | AW40: 41877 | AX40: 36.52 | AY40: 0
A41: 42471 | B41: 40.65 | C41: 0 | D41: 43559 | E41: 9.82 | F41: 0 | G41: 44546 | H41: =0.0257*(9.09^3) - 0.274*(9^2) - 0.0495*(9) + 9.249 -> 5.9124983 | I41: 1 | J41: 41976 | K41: 72.6 | L41: 0 | M41: 38378 | N41: 4.3 | O41: 0 | P41: 38378 | Q41: 5.39 | R41: 0 | S41: 38378 | T41: 29.27 | U41: 0 | V41: 38378 | W41: 2.55 | X41: 0 | Y41: 38068 | Z41: 29.6 | AA41: 0 | AB41: 38068 | AC41: 6.97 | AD41: 0 | AE41: 41471 | AF41: 92.41 | AG41: 0 | AH41: 40278 | AI41: 61.18 | AJ41: 0 | AK41: 41793 | AL41: 37.91 | AM41: 0 | AN41: 41764 | AO41: 67.13 | AP41: 0 | AT41: 41793 | AU41: 71.52 | AV41: 0 | AW41: 41906 | AX41: 36.61 | AY41: 0
A42: 42591 | B42: 40.57 | C42: 0 | D42: 43588 | E42: 9.7916667 | F42: 0 | G42: 44625 | H42: =0.0257*(9.099^3) - 0.274*(9^2) - 0.0495*(9) + 9.249 -> 5.9698908 | I42: 0 | J42: 42009 | K42: 73.35 | L42: 0 | M42: 38404 | N42: 4.33 | O42: 0 | P42: 38404 | Q42: 5.42 | R42: 0 | S42: 38404 | T42: 29.32 | U42: 0 | V42: 38404 | W42: 2.6 | X42: 0 | Y42: 38078 | Z42: 29.7 | AA42: 0 | AB42: 38078 | AC42: 6.9 | AD42: 0 | AE42: 41506 | AF42: 92.5 | AG42: 0 | AH42: 40279 | AI42: 61.18 | AJ42: 0 | AK42: 41830 | AL42: 37.74 | AM42: 0 | AN42: 41793 | AO42: 67.32 | AP42: 0 | AT42: 41830 | AU42: 71.75 | AV42: 0 | AW42: 41936 | AX42: 36.7 | AY42: 0
A43: 42702 | B43: 41.1 | C43: 0 | D43: 43905 | E43: 9.77 | F43: 1 | G43: 44826 | H43: =0.0257*(9.11^3) - 0.274*(9^2) - 0.0495*(9) + 9.249 -> 6.0401914 | I43: 1 | J43: 42157 | K43: 73.79 | L43: 0 | M43: 38439 | N43: 4.41 | O43: 0 | P43: 38439 | Q43: 5.48 | R43: 0 | S43: 38439 | T43: 29.88 | U43: 0 | V43: 38439 | W43: 2.69 | X43: 0 | Y43: 38090 | Z43: 29.8 | AA43: 0 | AB43: 38090 | AC43: 7.12 | AD43: 0 | AE43: 41537 | AF43: 92.81 | AG43: 0 | AH43: 40280 | AI43: 61.18 | AJ43: 0 | AK43: 41877 | AL43: 37.81 | AM43: 0 | AN43: 41830 | AO43: 67.47 | AP43: 0 | AT43: 41936 | AU43: 72.27 | AV43: 0 | AW43: 41976 | AX43: 36.27 | AY43: 0
A44: 42774 | B44: 41.59 | C44: 0 | D44: 44100 | E44: 9.82 | F44: 1 | G44: 44924 | H44: =0.0257*(9.103^3) - 0.274*(9^2) - 0.0495*(9) + 9.249 -> 5.995435 | I44: 0 | J44: 42220 | K44: 74.05 | L44: 0 | M44: 38446 | N44: 4.56 | O44: 0 | P44: 38446 | Q44: 5.62 | R44: 0 | S44: 38446 | T44: 29.56 | U44: 0 | V44: 38446 | W44: 2.71 | X44: 0 | Y44: 38107 | Z44: 29.82 | AA44: 0 | AB44: 38107 | AC44: 6.97 | AD44: 0 | AE44: 41555 | AF44: 92.76 | AG44: 0 | AH44: 40281 | AI44: 61.18 | AJ44: 0 | AK44: 41906 | AL44: 37.95 | AM44: 0 | AN44: 41877 | AO44: 67.69 | AP44: 0 | AT44: 41976 | AU44: 72.58 | AV44: 0 | AW44: 42009 | AX44: 36.97 | AY44: 0
A45: 42865 | B45: 41.79 | C45: 0 | D45: 44205 | E45: 9.912 | F45: 0 | G45: 45088 | H45: =0.0257*(9.2^3) - 0.274*(9^2) - 0.0495*(9) + 9.249 -> 6.6217816 | I45: 0 | J45: 42255 | K45: 74.17 | L45: 0 | M45: 38453 | N45: 4.62 | O45: 0 | P45: 38453 | Q45: 5.63 | R45: 0 | S45: 38453 | T45: 29.62 | U45: 0 | V45: 38453 | W45: 2.66 | X45: 0 | Y45: 38124 | Z45: 29.8 | AA45: 0 | AB45: 38124 | AC45: 6.92 | AD45: 0 | AE45: 41604 | AF45: 93.1 | AG45: 0 | AH45: 40282 | AI45: 61.19 | AJ45: 0 | AK45: 41936 | AL45: 37.82 | AM45: 0 | AN45: 41906 | AO45: 67.9 | AP45: 0 | AT45: 42009 | AU45: 72.55 | AV45: 0 | AW45: 42107 | AX45: 37.14 | AY45: 0
A46: 42887 | B46: 41.93 | C46: 0 | D46: 44369 | E46: 9.873 | F46: 0 | G46: 45238 | H46: =0.0257*(9.3^3) - 0.274*(9^2) - 0.0495*(9) + 9.249 -> 7.2814749 | I46: 1 | J46: 42292 | K46: 74.28 | L46: 0 | M46: 38467 | N46: 4.7 | O46: 0 | P46: 38467 | Q46: 5.66 | R46: 0 | S46: 38461 | T46: 30.16 | U46: 0 | V46: 38461 | W46: 2.71 | X46: 0 | Y46: 38133 | Z46: 29.6 | AA46: 0 | AB46: 38133 | AC46: 6.82 | AD46: 0 | AE46: 41617 | AF46: 93.15 | AG46: 0 | AH46: 40283 | AI46: 61.19 | AJ46: 0 | AK46: 41976 | AL46: 37.77 | AM46: 0 | AN46: 41936 | AO46: 67.71 | AP46: 0 | AT46: 42157 | AU46: 73.5 | AV46: 0 | AW46: 42157 | AX46: 37.22 | AY46: 0
A47: 42955 | B47: 41.8 | C47: 0 | D47: 44534 | E47: 9.72 | F47: 0 | G47: 45349 | H47: =0.0257*(9.25^3) - 0.274*(9^2) - 0.0495*(9) + 9.249 -> 6.9498453 | I47: 0 | J47: 42353 | K47: 74.49 | L47: 0 | M47: 38474 | N47: 4.75 | O47: 0 | P47: 38474 | Q47: 5.65 | R47: 0 | S47: 38596 | T47: 30.44 | U47: 0 | V47: 38596 | W47: 2.55 | X47: 0 | Y47: 38153 | Z47: 29.04 | AA47: 0 | AB47: 38153 | AC47: 6.57 | AD47: 0 | AE47: 41647 | AF47: 93.35 | AG47: 0 | AH47: 40284 | AI47: 61.19 | AJ47: 0 | AK47: 42009 | AL47: 37.65 | AM47: 0 | AN47: 41976 | AO47: 68.06 | AP47: 0 | AT47: 42220 | AU47: 73.82 | AV47: 0 | AW47: 42221 | AX47: 37.39 | AY47: 0
A48: 43048 | B48: 41.99 | C48: 0 | D48: 44637 | E48: 9.81 | F48: 0 | G48: 45581 | H48: =0.0257*(9.19^3) - 0.274*(9^2) - 0.0495*(9) + 9.249 -> 6.5565951 | I48: 1 | J48: 42387 | K48: 74.6 | L48: 0 | M48: 38485 | N48: 4.8 | O48: 0 | P48: 38485 | Q48: 5.6 | R48: 0 | S48: 38653 | T48: 30.56 | U48: 0 | V48: 38653 | W48: 2.9 | X48: 0 | Y48: 38161 | Z48: 29.35 | AA48: 0 | AB48: 38161 | AC48: 6.62 | AD48: 0 | AE48: 41683 | AF48: 93.17 | AG48: 0 | AH48: 40287 | AI48: 59.72 | AJ48: 0 | AK48: 42107 | AL48: 38.28 | AM48: 0 | AN48: 42009 | AO48: 67.99 | AP48: 0 | AT48: 42353 | AU48: 74.4 | AV48: 0 | AW48: 42292 | AX48: 37.58 | AY48: 0
A49: 43160 | B49: 42.107111 | C49: 1 | D49: 44834 | E49: 9.9 | F49: 1 | G49: 45731 | H49: =0.0257*(9.26^3) - 0.274*(9^2) - 0.0495*(9) + 9.249 -> 7.0158853 | I49: 1 | J49: 42429 | K49: 74.87 | L49: 0 | M49: 38592 | N49: 5.15 | O49: 0 | P49: 38592 | Q49: 5.63 | R49: 0 | S49: 38687 | T49: 30.62 | U49: 0 | V49: 38687 | W49: 2.71 | X49: 0 | Y49: 38169 | Z49: 29.73 | AA49: 0 | AB49: 38169 | AC49: 6.89 | AD49: 0 | AE49: 41731 | AF49: 93.8 | AG49: 0 | AH49: 40501 | AI49: 58.35 | AJ49: 0 | AK49: 42157 | AL49: 38 | AM49: 0 | AN49: 42157 | AO49: 68.64 | AP49: 0 | AT49: 42429 | AU49: 75.14 | AV49: 0 | AW49: 42353 | AX49: 37.71 | AY49: 0
...

Sheet Gradientes x Pozo
AZ1: Cerrado
A2: Sampues - # 52-II-C-PZ-01 | D2: Finca el socorro (Ovejas) - # 44-II-D-PO-02 | G2: Ovejas - # 44-II-D-PO-14 | J2: Los Palmitos - # 44-IV-B-PZ-01 Piñal | M2: Morroa (Bremen) - # 44-IV-C-PZ-01 A | P2: Bremen - # 44-IV-C-PZ-01 B | S2: Las Tinas (Morroa) - # 44-IV-C-PZ-02 A | V2: Las Tinas (Morroa) - # 44-IV-C-PZ-02 B | Y2: Arroyo salida a Betulia (Corozal) - # 44-IV-D-PZ-01 A | AB2: Arroyo salida a Betulia (Corozal) - # 44-IV-D-PZ-01 B | AE2: Sabanas de cali (El Tesoro) - # 44-IV-D-PZ-02 | AH2: Sabanas de cali (El Tesoro) - # 44-IV-D-PZ-04 | AK2: Basurero Viejo, Pileta (Corozal) - # 52-II-B-PZ-01 A | AN2: Corozal - # 44-IV-D-PO-14 | AQ2: Corozal - # 44-IV-D-PZ-20 | AT2: Corozal - # 44-IV-D-PZ-22 | AW2: Cantagallo - # 52-II-A-PZ-01 Corozal | AZ2: Basurero Viejo, Pileta (Corozal) - # 52-II-B-PZ-01 B
